<mujoco model='clevr'>
  <compiler inertiafromgeom='true' angle='radian' coordinate='local'/>
  <option timestep='0.01' gravity='0 0 -9.8' iterations='20' integrator='Euler' />

  <default>
    <joint armature='0.04' damping='1' limited='true'/>
    <geom friction='.8 .1 .1' density='300' margin='0.002' condim='1' contype='1' conaffinity='0'/>
  </default>

  <worldbody>
    <light diffuse='.5 .5 .5' pos='0 0 3' dir='0 0 -1'/>
    <geom name='table' type='plane' pos='0 0.5 -0.325' size='1 1 0.1' contype='1' conaffinity='1'/>

    <!--<body name='object' pos='0.55 -0.3 -0.275' >-->
    <body name='object1' pos='-0.80 -0.1 -0.225' >
      <!--<geom rgba='1 1 1 0' type='sphere' size='0.05 0.05 0.05' density='0.00001' conaffinity='0'/>-->
      <geom rgba='1 1 1 1' type='cylinder' size='0.05 0.1 0.1' density='0.00001' contype='1' conaffinity='0'/>
      <joint name='obj1_slidey' type='slide' pos='0 0 0' axis='0 1 0' range='-10.3213 10.3' damping='0.5'/>
      <joint name='obj1_slidex' type='slide' pos='0 0 0' axis='1 0 0' range='-10.3213 10.3' damping='0.5'/>
    </body>

    <body name='object2' pos='0.60 -0.05 -0.275' >
      <!--<geom rgba='1 1 1 0' type='sphere' size='0.05 0.05 0.05' density='0.00001' conaffinity='0'/>-->
      <geom rgba='0 1 1 1' type='cylinder' size='0.05 0.05 0.05' density='0.00001' contype='1' conaffinity='0'/>
      <joint name='obj2_slidey' type='slide' pos='0 0 0' axis='0 1 0' range='-10.3213 10.3' damping='0.5'/>
      <joint name='obj2_slidex' type='slide' pos='0 0 0' axis='1 0 0' range='-10.3213 10.3' damping='0.5'/>
    </body>

    <body name='object3' pos='0.30 0.60 -0.225' >
      <!--<geom rgba='1 1 1 0' type='box' size='0.1 0.1 0.1' density='0.00001' conaffinity='0'/>-->
      <geom rgba='0 1 0.5 1' type='box' size='0.1 0.1 0.1' density='0.00001' contype='1' conaffinity='0'/>
      <joint name='obj3_slidey' type='slide' pos='0 0 0' axis='0 1 0' range='-10.3213 10.3' damping='0.5'/>
      <joint name='obj3_slidex' type='slide' pos='0 0 0' axis='1 0 0' range='-10.3213 10.3' damping='0.5'/>
    </body>

    <body name='r_wrist_flex_link' pos='0 0.8 -0.1'>
      <geom name='wf' type='capsule' fromto='0 -0.05 0 0 0.05 0' size='0.01' />
      <joint name='r_wrist_flex_joint_y' type='slide' pos='0 0 0' axis='0 1 0' range='-10.3213 10.3' damping='.1' />
      <joint name='r_wrist_flex_joint_x' type='slide' pos='0 0 0' axis='1 0 0' range='-10.3213 10.3' damping='.1' />
      <body name='r_wrist_roll_link' pos='0 0 0'>
        <joint name='r_wrist_roll_joint' type='hinge' pos='0 0 0' limited='true' axis='1 0 0' damping='0.1' range='-1.5 1.5'/>
        <body name='tips_arm' pos='0 0 0'>
          <geom name='tip_arml' type='sphere' pos='-0.1 0 -0.1' size='0.01' />
          <geom name='tip_armr' type='sphere' pos='0.1 0 -0.1' size='0.01' />
        </body>
        <geom type='capsule' fromto='-0.1 0 0. +0.1 0 0' size='0.02' contype='1' conaffinity='1' />
        <geom type='capsule' fromto='-0.1 0. 0 -0.1 0 -0.1' size='0.02' contype='1' conaffinity='1' />
        <geom type='capsule' fromto='0.1 0. 0 0.1 0 -0.1' size='0.02' contype='1' conaffinity='1' />
      </body>
    </body>
  </worldbody>

  <actuator>
    <motor joint='r_wrist_flex_joint_y' ctrlrange='-2.0 2.0' ctrllimited='true' />
    <motor joint='r_wrist_flex_joint_x' ctrlrange='-2.0 2.0' ctrllimited='true' />
  </actuator>

</mujoco>
