<mujoco model='clevr'>
  <compiler inertiafromgeom='true' angle='radian' coordinate='local'/>
  <option timestep='0.01' gravity='0 0 -9.8' iterations='20' integrator='Euler' />

  <default>
    <joint armature='0.04' damping='1' limited='true'/>
    <geom friction='.8 .1 .1' density='300' margin='0.002' condim='1' contype='1' conaffinity='0'/>
  </default>

  <worldbody>
    <light diffuse='.5 .5 .5' pos='0 0 3' dir='0 0 -1'/>
    <geom name='table' type='plane' pos='0 0.5 -0.325' size='1 1 0.1' contype='1' conaffinity='1'/>

    <!--<body name='object' pos='0.55 -0.3 -0.275' >-->
    <body name='obj1' pos='-0.80 -0.1 -0.225' >
      <!--<geom rgba='1 1 1 0' type='sphere' size='0.05 0.05 0.05' density='0.00001' conaffinity='0'/>-->
      <geom rgba='1 1 1 1' type='cylinder' size='0.05 0.1 0.1' density='0.00001' contype='1' conaffinity='0'/>
      <joint name='obj1_slidey' type='slide' pos='0 0 0' axis='0 1 0' range='-10.3213 10.3' damping='0.5'/>
      <joint name='obj1_slidex' type='slide' pos='0 0 0' axis='1 0 0' range='-10.3213 10.3' damping='0.5'/>
    </body>

    <body name='obj2' pos='0.60 -0.05 -0.275' >
      <!--<geom rgba='1 1 1 0' type='sphere' size='0.05 0.05 0.05' density='0.00001' conaffinity='0'/>-->
      <geom rgba='0 1 1 1' type='cylinder' size='0.05 0.05 0.05' density='0.00001' contype='1' conaffinity='0'/>
      <joint name='obj2_slidey' type='slide' pos='0 0 0' axis='0 1 0' range='-10.3213 10.3' damping='0.5'/>
      <joint name='obj2_slidex' type='slide' pos='0 0 0' axis='1 0 0' range='-10.3213 10.3' damping='0.5'/>
    </body>

    <body name='obj3' pos='0.30 0.60 -0.225' >
      <!--<geom rgba='1 1 1 0' type='box' size='0.1 0.1 0.1' density='0.00001' conaffinity='0'/>-->
      <geom rgba='0 1 0.5 1' type='box' size='0.1 0.1 0.1' density='0.00001' contype='1' conaffinity='0'/>
      <joint name='obj3_slidey' type='slide' pos='0 0 0' axis='0 1 0' range='-10.3213 10.3' damping='0.5'/>
      <joint name='obj3_slidex' type='slide' pos='0 0 0' axis='1 0 0' range='-10.3213 10.3' damping='0.5'/>
    </body>

    <body pos='-0.4793 -0.1582 -0.2228' name='obj0'>
      <geom size='0.1021 0.1021 0.1021' conaffinity='1' contype='1' density='1' rgba='0.2 1 0 1' type='box'/>
      <joint pos='0 0 0' damping='0.75' type='free' limited='false' name='obj3_slide'/>
    </body>

    <body pos='0.3660 0.4967 -0.2166' name='obj4'>
      <geom size='0.1083 0.0902 0.05' conaffinity='1' contype='1' density='1' rgba='0.2 1 0 1' type='box'/>
      <joint pos='0 0 0' damping='0.75' type='free' limited='false' name='obj4_slide'/>
    </body>

    <body pos='0.469675315258 -0.205294383583 -0.2' name='point_mass'>
      <geom type='sphere' contype='1' conaffinity='0' rgba='1 1 1 1' density='0.5' size='0.05' name='pm'/>
      <joint type='slide' axis='1 0 0' damping='0.5' pos='0 0 0' name='pm_joint_x' range='-10.3213 10.3'/>
      <joint type='slide' axis='0 1 0' damping='0.5' pos='0 0 0' name='pm_joint_y' range='-10.3213 10.3'/>
    </body>

  </worldbody>

  <actuator>
    <motor joint='pm_joint_x' ctrllimited='true' ctrlrange='-2.0 2.0'/>
    <motor joint='pm_joint_y' ctrllimited='true' ctrlrange='-2.0 2.0'/>
  </actuator>

</mujoco>
